<?xml version='1.0'?>
<sdf version='1.4'>
  <model name="diffdrive">
  <static>false</static>

    <link name='chassis'>
      <pose>0 0 0.1 0 0 0</pose>
      <inertial>
        <mass>10.0</mass>
        <pose>0.0 0 0.1 0 0 0</pose>
        <inertia>
          <ixx>0.5</ixx>
          <iyy>1.0</iyy>
          <izz>0.1</izz>
        </inertia>
      </inertial>
      <collision name='collision'>
      <geometry>
        <box>
          <size>.4 .2 .1</size>
        </box>
      </geometry>
      </collision>
      <visual name='visual'>
        <pose>0 0 0.0 0 0 0</pose>
        <geometry>
          <box>
            <size>.4 .2 .1</size>
        </box>
      </geometry>
      </visual>
      <collision name='caster_collision'>
      <pose>-0.15 0 -0.05 0 0 0</pose>
      <geometry>
        <sphere>
          <radius>.05</radius>
        </sphere>
      </geometry>
      <surface>
        <friction>
          <ode>
          <mu>0</mu>
          <mu2>0</mu2>
          <slip1>1.0</slip1>
          <slip2>1.0</slip2>
          </ode>
        </friction>
        </surface>
      </collision>
      <visual name='caster_visual'>
        <pose>-0.15 0 -0.05 0 0 0</pose>
        <geometry>
          <sphere>
            <radius>.05</radius>
          </sphere>
        </geometry>
      </visual>
    </link>

    <collision name='caster_collision'>
      <pose>-0.15 0 -0.05 0 0 0</pose>
      <geometry>
        <sphere>
          <radius>.05</radius>
        </sphere>
      </geometry>
      <surface>
        <friction>
          <ode>
          <mu>0</mu>
          <mu2>0</mu2>
          <slip1>1.0</slip1>
          <slip2>1.0</slip2>
          </ode>
        </friction>
        </surface>
    </collision>
    <visual name='caster_visual'>
      <pose>-0.15 0 -0.05 0 0 0</pose>
      <geometry>
        <sphere>
          <radius>.05</radius>
        </sphere>
      </geometry>
    </visual>
    

    <link name="left_wheel">
      <pose>0.1 0.13 0.1 0 1.5707 1.5707</pose>
      <collision name="collision">
        <geometry>
          <cylinder>
            <radius>.1</radius>
            <length>.05</length>
          </cylinder>
        </geometry>
      </collision>
      <visual name="visual">
        <geometry>
        <cylinder>
            <radius>.1</radius>
            <length>.05</length>
          </cylinder>
        </geometry>
      </visual>
    </link>

    <link name="right_wheel">
      <pose>0.1 -0.13 0.1 0 1.5707 1.5707</pose>
      <collision name="collision">
        <geometry>
          <cylinder>
            <radius>.1</radius>
            <length>.05</length>
          </cylinder>
        </geometry>
      </collision>
      <visual name="visual">
        <geometry>
          <cylinder>
            <radius>.1</radius>
            <length>.05</length>
          </cylinder>
        </geometry>
      </visual>
    </link>

    <joint type="revolute" name="left_wheel_joint">
      <pose>0 0 -0.03 0 0 0</pose>
      <child>left_wheel</child>
      <parent>chassis</parent>
      <axis>
        <xyz>0 1 0</xyz>
      </axis>
    </joint>

    <joint type="revolute" name="right_wheel_joint">
      <pose>0 0 0.03 0 0 0</pose>
      <child>right_wheel</child>
      <parent>chassis</parent>
      <axis>
        <xyz>0 1 0</xyz>
      </axis>
    </joint>

    <plugin name="differential_drive_controller" filename="libgazebo_ros_diff_drive.so">
      <alwaysOn>true</alwaysOn>
      <updateRate>20</updateRate>

      <left_joint>left_wheel_joint</left_joint>
      <right_joint>right_wheel_joint</right_joint>

      <wheel_separation>0.4</wheel_separation>
      <wheel_diameter>0.1</wheel_diameter>

      <max_wheel_torque>20</max_wheel_torque>
      <max_wheel_acceleration>1.0</max_wheel_acceleration>

      <command_topic>cmd_vel</command_topic>
      <command_topic>odom</command_topic>
      <publish_odom>true</publish_odom>
      <publish_odom_tf>false</publish_odom_tf>
      <publish_wheel_tf>true</publish_wheel_tf>
      <odometry_topic>odom</odometry_topic>
      <odometry_frame>odom</odometry_frame>
      <robot_base_frame>base_footprint</robot_base_frame>
    </plugin>


      
  </model>
</sdf>